Workbook

Sheet 1. Menu Audit
A1: Menu Item | B1: Category | C1: Menu Price (₱) | D1: # Ingredient Lines | E1: Inventory Coverage
A2: Unli Wings - Classic Buffalo | B2: Unlimited Wings - 14 Flavors | C2: 399 | D2: 11 | E2: Fully Covered (Table 4)
A3: Unli Wings - Mango Habanero | B3: Unlimited Wings - 14 Flavors | C3: 399 | D3: 13 | E3: Fully Covered (Table 4)
A4: Unli Wings - Salted Egg | B4: Unlimited Wings - 14 Flavors | C4: 399 | D4: 15 | E4: Fully Covered (Table 4)
A5: Unli Wings - Lemon Glazed | B5: Unlimited Wings - 14 Flavors | C5: 399 | D5: 15 | E5: Fully Covered (Table 4)
A6: Unli Wings - Original | B6: Unlimited Wings - 14 Flavors | C6: 399 | D6: 8 | E6: Fully Covered (Table 4)
A7: Unli Wings - Korean BBQ | B7: Unlimited Wings - 14 Flavors | C7: 399 | D7: 14 | E7: Fully Covered (Table 4)
A8: Unli Wings - Garlic Parmesan | B8: Unlimited Wings - 14 Flavors | C8: 399 | D8: 13 | E8: Fully Covered (Table 4)
A9: Unli Wings - Soy Garlic | B9: Unlimited Wings - 14 Flavors | C9: 399 | D9: 16 | E9: Fully Covered (Table 4)
A10: Unli Wings - Teriyaki | B10: Unlimited Wings - 14 Flavors | C10: 399 | D10: 16 | E10: Fully Covered (Table 4)
A11: Unli Wings - Honey Sriracha | B11: Unlimited Wings - 14 Flavors | C11: 399 | D11: 13 | E11: Fully Covered (Table 4)
A12: Unli Wings - Snow Cheese | B12: Unlimited Wings - Premium Flavors | C12: 429 | D12: 12 | E12: Fully Covered (Table 4)
A13: Unli Wings - Panda Express Orange Chicken | B13: Unlimited Wings - Premium Flavors | C13: 414 | D13: 18 | E13: Fully Covered (Table 4)
... A49: Wings Platter 36 pcs (6 Flavors) | B49: Ala Carte Wings | C49: 1125 | D49: 11 | E49: Fully Covered (Table 4)

Sheet 3. Standardized Recipes
A1: Menu Item | B1: Category | C1: Standard Serving Size | D1: Servings Produced | E1: Full Ingredient Breakdown (qty + unit) | F1: Preparation / Cooking Method
A2: Unli Wings - Classic Buffalo | B2: Unlimited Wings - 14 Flavors | C2: 3 pcs fried wings | D2: 1 | E2: Chicken Wings 3pc; All-Purpose Flour 22.5g; Cornstarch 15g; Baking Powder 1g; Salt 1g; Black Pepper (ground) 0.5g; Garlic Powder 0.5g; Cooking Oil 15ml; Hot Sauce 22.5ml; Butter 9g; Worcestershire Sauce 1.5ml | F2: Season/dredge as listed, deep-fry in the batch's cooking oil until golden and cooked through, drain, then toss/glaze/finish per the flavor's sauce.
A3: Unli Wings - Mango Habanero | B3: Unlimited Wings - 14 Flavors | C3: 3 pcs fried wings | D3: 1 | E3: Chicken Wings 3pc; All-Purpose Flour 22.5g; Cornstarch 15g; Baking Powder 1g; Salt 1g; Black Pepper (ground) 0.5g; Garlic Powder 0.5g; Cooking Oil 15ml; Mango Nectar/Puree 27.5ml; Habanero Sauce 5ml; Honey 4g; Butter 4g; Vinegar (cane/white) 1.5ml | F3: Season/dredge as listed, deep-fry in the batch's cooking oil until golden and cooked through, drain, then toss/glaze/finish per the flavor's sauce.
A4: Unli Wings - Salted Egg | B4: Unlimited Wings - 14 Flavors | C4: 3 pcs fried wings | D4: 1 | E4: Chicken Wings 3pc; All-Purpose Flour 22.5g; Cornstarch 15g; Baking Powder 1g; Salt 1g; Black Pepper (ground) 0.5g; Garlic Powder 0.5g; Cooking Oil 15ml; Salted Egg Yolk 1pc; Butter 7.5g; Garlic (Minced, g) 2.5g; Evaporated Milk 10ml; Chili Flakes 0.5g; Curry Leaves 1g; Curry Powder 0.1g | F4: Season/dredge as listed, deep-fry in the batch's cooking oil until golden and cooked through, drain, then toss/glaze/finish per the flavor's sauce.
A5: Unli Wings - Lemon Glazed | B5: Unlimited Wings - 14 Flavors | C5: 3 pcs fried wings | D5: 1 | E5: Chicken Wings 3pc; All-Purpose Flour 22.5g; Cornstarch 15g; Baking Powder 1g; Salt 1g; Black Pepper (ground) 0.5g; Garlic Powder 0.5g; Cooking Oil 15ml; Lemon Juice 10ml; Lemon Zest 0.5g; Honey 9g; Butter 4g; Garlic (Minced, g) 1g; Cornstarch 1g; Water 5ml | F5: Season/dredge as listed, deep-fry in the batch's cooking oil until golden and cooked through, drain, then toss/glaze/finish per the flavor's sauce.
A6: Unli Wings - Original | B6: Unlimited Wings - 14 Flavors | C6: 3 pcs fried wings | D6: 1 | E6: Chicken Wings 3pc; All-Purpose Flour 22.5g; Cornstarch 15g; Baking Powder 1g; Salt 1g; Black Pepper (ground) 0.5g; Garlic Powder 1g; Cooking Oil 15ml | F6: Season/dredge as listed, deep-fry in the batch's cooking oil until golden and cooked through, drain, then toss/glaze/finish per the flavor's sauce.
A7: Unli Wings - Korean BBQ | B7: Unlimited Wings - 14 Flavors | C7: 3 pcs fried wings | D7: 1 | E7: Chicken Wings 3pc; All-Purpose Flour 22.5g; Cornstarch 15g; Baking Powder 1g; Salt 1g; Black Pepper (ground) 0.5g; Garlic Powder 0.5g; Cooking Oil 15ml; Korean BBQ Sauce 22.5ml; Soy Sauce 2.5ml; Honey 4g; Garlic (Minced, g) 2g; Sesame Oil 1ml; Sesame Seeds 1g | F7: Season/dredge as listed, deep-fry in the batch's cooking oil until golden and cooked through, drain, then toss/glaze/finish per the flavor's sauce.
A8: Unli Wings - Garlic Parmesan | B8: Unlimited Wings - 14 Flavors | C8: 3 pcs fried wings | D8: 1 | E8: Chicken Wings 3pc; All-Purpose Flour 22.5g; Cornstarch 15g; Baking Powder 1g; Salt 1g; Black Pepper (ground) 0.5g; Garlic Powder 0.5g; Cooking Oil 15ml; Butter 9g; Garlic (Minced, g) 3g; Parmesan Cheese 9g; Parsley, fresh 1g; Black Pepper (ground) 0.5g | F8: Season/dredge as listed, deep-fry in the batch's cooking oil until golden and cooked through, drain, then toss/glaze/finish per the flavor's sauce.
A9: Unli Wings - Soy Garlic | B9: Unlimited Wings - 14 Flavors | C9: 3 pcs fried wings | D9: 1 | E9: Chicken Wings 3pc; All-Purpose Flour 22.5g; Cornstarch 15g; Baking Powder 1g; Salt 1g; Black Pepper (ground) 0.5g; Garlic Powder 0.5g; Cooking Oil 15ml; Soy Sauce 12.5ml; Honey 6g; Brown Sugar 3g; Garlic (Minced, g) 3g; Ginger 1.5g; Mirin 7.5ml; Sesame Oil 1.5ml; Sesame Seeds 1g | F9: Season/dredge as listed, deep-fry in the batch's cooking oil until golden and cooked through, drain, then toss/glaze/finish per the flavor's sauce.
A10: Unli Wings - Teriyaki | B10: Unlimited Wings - 14 Flavors | C10: 3 pcs fried wings | D10: 1 | E10: Chicken Wings 3pc; All-Purpose Flour 22.5g; Cornstarch 15g; Baking Powder 1g; Salt 1g; Black Pepper (ground) 0.5g; Garlic Powder 0.5g; Cooking Oil 15ml; Soy Sauce 12.5ml; Mirin 7.5ml; Brown Sugar 6g; Ginger 1g; Garlic (Minced, g) 1g; Cornstarch 1g; Water 5ml; Sesame Seeds 1g | F10: Season/dredge as listed, deep-fry in the batch's cooking oil until golden and cooked through, drain, then toss/glaze/finish per the flavor's sauce.
A11: Unli Wings - Honey Sriracha | B11: Unlimited Wings - 14 Flavors | C11: 3 pcs fried wings | D11: 1 | E11: Chicken Wings 3pc; All-Purpose Flour 22.5g; Cornstarch 15g; Baking Powder 1g; Salt 1g; Black Pepper (ground) 0.5g; Garlic Powder 0.5g; Cooking Oil 15ml; Sriracha Sauce 17.5ml; Honey 6g; Butter 4g; Calamansi Juice 2ml; Garlic Powder 0.5g | F11: Season/dredge as listed, deep-fry in the batch's cooking oil until golden and cooked through, drain, then toss/glaze/finish per the flavor's sauce.
A12: Unli Wings - Snow Cheese | B12: Unlimited Wings - Premium Flavors | C12: 3 pcs fried wings | D12: 1 | E12: Chicken Wings 3pc; All-Purpose Flour 22.5g; Cornstarch 15g; Baking Powder 1g; Salt 1g; Black Pepper (ground) 0.5g; Garlic Powder 0.5g; Cooking Oil 15ml; Cheese Powder 9g; Milk Powder 2.5g; Powdered Sugar 1.5g; Parmesan Cheese 2.5g | F12: Season/dredge as listed, deep-fry in the batch's cooking oil until golden and cooked through, drain, then toss/glaze/finish per the flavor's sauce.
A13: Unli Wings - Panda Express Orange Chicken | B13: Unlimited Wings - Premium Flavors | C13: 3 pcs fried wings | D13: 1 | E13: Chicken Wings 3pc; All-Purpose Flour 22.5g; Cornstarch 15g; Baking Powder 1g; Salt 1g; Black Pepper (ground) 0.5g; Garlic Powder 0.5g; Cooking Oil 15ml; Orange Juice 17.5ml; Orange Zest 0.5g; Soy Sauce 4ml; Brown Sugar 6g; Rice Vinegar 2.5ml; Garlic (Minced, g) 1.5g; Ginger 1g; Cornstarch 1.5g; Water 5ml; Chili Flakes 0.5g | F13: Season/dredge as listed, deep-fry in the batch's cooking oil until golden and cooked through, drain, then toss/glaze/finish per the flavor's sauce.
... A49: Wings Platter 36 pcs (6 Flavors) | B49: Ala Carte Wings | C49: 36 pcs wings (6 flavors) + fries | D49: 1 | E49: Chicken Wings 36pcs; All-Purpose Flour 180g; Cornstarch 90g; Salt 12g; Black Pepper 3g; Garlic Powder 6g; Paprika 6g; Cooking Oil 180ml; Wing Sauce (Selected Flavors, 30g x 6) 180g; Frozen French Fries 720g; Cooking Oil for Fries 90ml | F49: Season/dredge as listed, deep-fry in the batch's cooking oil until golden and cooked through, drain, then toss/glaze/finish each 6-wing group in its own chosen flavor's sauce.

Sheet 4. Master Ingredient Inventory
A1: Ingredient ID | B1: Ingredient Name | C1: Category | D1: Specification | E1: Purchase Unit | F1: Purchase Price (₱) | G1: Base Unit | H1: Base Qty per Purchase | I1: Cost per Base Unit (₱) | J1: Menu Items Using | K1: Storage Requirement | L1: Shelf Life (Unopened/Sealed) | M1: Shelf Life (Opened/Prepped) | N1: Inventory Status
A2: ING-001 | B2: All-Purpose Cream | C2: Dairy | D2: Dairy cream, UHT, food-service (all-purpose cream, ~25-30% fat -- NOT heavy/whipping cream, ~36%+ fat). Selected as the initial default for every recipe's generic "Cream" line (White Truffle Pasta, Spicy Tuna Linguine Pesto, Creamy Sausage Pasta) as well as Creamy Chicken & Mushroom Alfredo's own explicitly-named "All-Purpose Cream": all-purpose cream (e.g. Nestle All Purpose Cream, Alaska Crema) is the standard, shelf-stable cream used in Filipino/Filipino-Italian food-service kitchens for cream sauces, versus imported dairy heavy cream which is costlier and less commonly stocked. This is an EDITABLE initial default, not a confirmed Wings Theory product -- if the kitchen actually uses heavy/whipping cream or another product, update this row directly; the system does not silently substitute once the real product is confirmed. | E2: can/tetra (250ml) | F2: 75 | G2: ml | H2: 250 | I2: =IFERROR(F2/H2,0) -> 0.3 | J2: Creamy Chicken & Mushroom Alfredo, Creamy Sausage Pasta, Spicy Tuna Linguine Pesto, White Truffle Pasta | K2: Ambient (dry storage) | L2: 9-12 months (printed date) | M2: Opened: refrigerate, 3-4 days | N2: Existing
A3: ING-002 | B3: All-Purpose Flour | C3: Dry Goods | D3: Wheat flour, all-purpose | E3: kg | F3: 58 | G3: g | H3: 1000 | I3: =IFERROR(F3/H3,0) -> 0.058 | J3: 12 pcs (2 Flavors) Ala Carte Wing Rack, 6 pcs Wings (1 Flavor) with Fries & Ranch Dip, Creamy Chicken & Mushroom Alfredo, Fish & Chips with Tartar Sauce, Onion Rings, Pork Tonkatsu, Spicy Korean Wing Bowl, Sulit Deal-3 pcs Wings + Rice, Unli Wings - Cheese, Unli Wings - Classic Buffalo, Unli Wings - Garlic Parmesan, Unli Wings - Honey Sriracha, Unli Wings - Korean BBQ, Unli Wings - Korean Yangnyeum, Unli Wings - Lemon Glazed, Unli Wings - Mango Habanero, Unli Wings - Original, Unli Wings - Panda Express Orange Chicken, Unli Wings - Salted Egg, Unli Wings - Snow Cheese, Unli Wings - Soy Garlic, Unli Wings - Teriyaki, Wings Platter 6 pcs w/ Fries, Wings Platter 36 pcs (6 Flavors) | K3: Dry, sealed, ambient | L3: 9-12 months | M3: Opened: reseal airtight, 2-3 months | N3: Existing
A4: ING-003 | B4: Bacon | C4: Meat | D4: Cured pork bacon, sliced | E4: kg | F4: 380 | G4: g | H4: 1000 | I4: =IFERROR(F4/H4,0) -> 0.38 | J4: Bacon and 2 Egg, Cheesy Bacon Fries | K4: Chilled 0-4°C | L4: Per pack date (~30-45 days) | M4: Opened: 7 days chilled | N4: Existing
A5: ING-004 | B5: Baking Powder | C5: Dry Goods | D5: Double-acting baking powder | E5: kg | F5: 140 | G5: g | H5: 1000 | I5: =IFERROR(F5/H5,0) -> 0.14 | J5: Fish & Chips with Tartar Sauce, Onion Rings, Unli Wings - Cheese, Unli Wings - Classic Buffalo, Unli Wings - Garlic Parmesan, Unli Wings - Honey Sriracha, Unli Wings - Korean BBQ, Unli Wings - Korean Yangnyeum, Unli Wings - Lemon Glazed, Unli Wings - Mango Habanero, Unli Wings - Original, Unli Wings - Panda Express Orange Chicken, Unli Wings - Salted Egg, Unli Wings - Snow Cheese, Unli Wings - Soy Garlic, Unli Wings - Teriyaki | K5: Dry, sealed, ambient | L5: 12-18 months (printed date) | M5: Opened: 6 months | N5: Existing
A6: ING-005 | B6: Baking Soda | C6: Dry Goods | D6: Sodium bicarbonate, food grade | E6: kg | F6: 120 | G6: g | H6: 1000 | I6: =IFERROR(F6/H6,0) -> 0.12 | J6: Beef Tapa | K6: Dry, sealed, ambient | L6: 18-24 months | M6: Opened: 6 months | N6: Existing
A7: ING-006 | B7: Banana | C7: Produce | D7: Saba/Latundan, ripe | E7: kg | F7: 65 | G7: g | H7: 1000 | I7: =IFERROR(F7/H7,0) -> 0.065 | J7: Banana Milk Shake (Tall) | K7: Ambient/Chilled | L7: 3-7 days (ripening dependent) | M7: n/a | N7: Existing
A8: ING-007 | B8: Beef Sirloin | C8: Meat | D8: Beef sirloin, thinly sliced for tapa | E8: kg | F8: 420 | G8: g | H8: 1000 | I8: =IFERROR(F8/H8,0) -> 0.42 | J8: Beef Tapa | K8: Frozen -18°C | L8: 4-6 months | M8: Thawed: use within 24 hrs | N8: Existing
A9: ING-008 | B9: Black Pepper (ground) | C9: Spices | D9: Ground black pepper | E9: kg | F9: 650 | G9: g | H9: 1000 | I9: =IFERROR(F9/H9,0) -> 0.65 | J9: 12 pcs (2 Flavors) Ala Carte Wing Rack, 6 pcs Wings (1 Flavor) with Fries & Ranch Dip, Bacon and 2 Egg, Beef Tapa, Chicken Salpicao, Creamy Chicken & Mushroom Alfredo, Creamy Sausage Pasta, Fish & Chips with Tartar Sauce, Hungarian Sausage, Onion Rings, Pork Tocino, Pork Tonkatsu, Ranch Dip, Spam and Egg, Spicy Korean Wing Bowl, Spicy Tuna Linguine Pesto, Sulit Deal-3 pcs Wings + Rice, Taiwanese Pork Chop, Unli Wings - Cheese, Unli Wings - Classic Buffalo, Unli Wings - Garlic Parmesan, Unli Wings - Honey Sriracha, Unli Wings - Korean BBQ, Unli Wings - Korean Yangnyeum, Unli Wings - Lemon Glazed, Unli Wings - Mango Habanero, Unli Wings - Original, Unli Wings - Panda Express Orange Chicken, Unli Wings - Salted Egg, Unli Wings - Snow Cheese, Unli Wings - Soy Garlic, Unli Wings - Teriyaki, White Truffle Pasta, Wings Platter 6 pcs w/ Fries, Wings Platter 36 pcs (6 Flavors) | K9: Dry, sealed, ambient | L9: 24-36 months whole; 12-18 ground | M9: Opened: 12 months | N9: Consolidated
A10: ING-009 | B10: Black Tea Bag | C10: Beverages | D10: Black tea, individually bagged | E10: box (25pcs) | F10: 95 | G10: pc | H10: 25 | I10: =IFERROR(F10/H10,0) -> 3.8 | J10: 1 Pitcher Iced Tea | K10: Dry, sealed, ambient | L10: 18-24 months (printed date) | M10: Opened: 6-12 months | N10: Existing
A11: ING-010 | B11: Blueberry Syrup | C11: Beverages | D11: Blueberry flavoring syrup, food-service | E11: L | F11: 450 | G11: ml | H11: 1000 | I11: =IFERROR(F11/H11,0) -> 0.45 | J11: Blueberry Yogurt (Tall) | K11: Ambient before opening | L11: 2 years unopened | M11: Opened: 6-12 months, refrigerate | N11: Existing
A12: ING-011 | B12: Breadcrumbs (Regular) | C12: Dry Goods | D12: Plain dried breadcrumbs | E12: kg | F12: 95 | G12: g | H12: 1000 | I12: =IFERROR(F12/H12,0) -> 0.095 | J12: Onion Rings | K12: Dry, sealed, ambient | L12: 6-9 months | M12: Opened: reseal airtight, 1-2 months | N12: Existing
A13: ING-012 | B13: Brown Sugar | C13: Dry Goods | D13: Brown/muscovado sugar | E13: kg | F13: 82 | G13: g | H13: 1000 | I13: =IFERROR(F13/H13,0) -> 0.082 | J13: Beef Tapa, Chicken Salpicao, Taiwanese Pork Chop, Unli Wings - Panda Express Orange Chicken, Unli Wings - Soy Garlic, Unli Wings - Teriyaki | K13: Dry, sealed, ambient | L13: 18-24 months | M13: Opened: reseal airtight | N13: Consolidated
... A83: ING-082 | B83: Powdered Sugar | C83: Dry Goods | D83: Confectioner's/powdered sugar | E83: kg | F83: 95 | G83: g | H83: 1000 | I83: =IFERROR(F83/H83,0) -> 0.095 | J83: Unli Wings - Snow Cheese | K83: Dry, sealed, ambient | L83: 18-24 months | M83: Opened: reseal airtight | N83: Existing
A84: ING-083 | B84: Ranch Dip (prepared) | C84: Component | D84: Prepared ranch dip (see its own recipe: Mayonnaise, Fresh Milk, Garlic Powder, Onion Powder, Dried Parsley, Salt, Black Pepper) -- not purchased directly | E84: recipe yield | F84: ='7. Ingredient & Recipe Costing'!D34 -> 5.394 | G84: ml | H84: 32 | I84: =IFERROR(F84/H84,0) -> 0.1685625 | J84: 6 pcs Wings (1 Flavor) with Fries & Ranch Dip | K84: Chilled 0-4°C | L84: n/a (made in-house) | M84: 24-48 hours refrigerated | N84: Component (not purchased)
A85: ING-084 | B85: Red Chili / Finger Chili | C85: Produce | D85: Fresh red finger chili | E85: kg | F85: 160 | G85: g | H85: 1000 | I85: =IFERROR(F85/H85,0) -> 0.16 | J85: Chicken Salpicao | K85: Chilled 0-4°C | L85: 1-2 weeks | M85: n/a | N85: Existing
A86: ING-085 | B86: Rice Vinegar | C86: Condiments | D86: Rice vinegar | E86: L | F86: 150 | G86: ml | H86: 1000 | I86: =IFERROR(F86/H86,0) -> 0.15 | J86: Spicy Korean Wing Bowl, Unli Wings - Korean Yangnyeum, Unli Wings - Panda Express Orange Chicken | K86: Ambient, sealed | L86: 24 months+ | M86: Opened: 6-12 months | N86: Consolidated
A87: ING-086 | B87: Ripe Mango | C87: Produce | D87: Ripe mango, for shakes | E87: kg | F87: 110 | G87: g | H87: 1000 | I87: =IFERROR(F87/H87,0) -> 0.11 | J87: Mango Shake (Tall) | K87: Ambient/Chilled | L87: 3-5 days ripe | M87: Cut/pureed: 1-2 days chilled | N87: Existing
A88: ING-087 | B88: Royal (Can) | C88: Beverages | D88: Royal True Orange / RC Cola, 330ml can | E88: can (330ml) | F88: 38 | G88: can | H88: 1 | I88: =IFERROR(F88/H88,0) -> 38 | J88: Royal | K88: Ambient, sealed | L88: 6-9 months (printed date) | M88: n/a | N88: Existing
A89: ING-088 | B89: Salt | C89: Spices | D89: Iodized table salt | E89: kg | F89: 30 | G89: g | H89: 1000 | I89: =IFERROR(F89/H89,0) -> 0.03 | J89: 12 pcs (2 Flavors) Ala Carte Wing Rack, 6 pcs Wings (1 Flavor) with Fries & Ranch Dip, Bacon and 2 Egg, Beef Tapa, Chicken Salpicao, Creamy Chicken & Mushroom Alfredo, Creamy Sausage Pasta, Fish & Chips with Tartar Sauce, Hungarian Sausage, Onion Rings, Pork Tocino, Pork Tonkatsu, Ranch Dip, Spam and Egg, Spicy Korean Wing Bowl, Spicy Tuna Linguine Pesto, Sulit Deal-3 pcs Wings + Rice, Taiwanese Pork Chop, Unli Wings - Cheese, Unli Wings - Classic Buffalo, Unli Wings - Garlic Parmesan, Unli Wings - Honey Sriracha, Unli Wings - Korean BBQ, Unli Wings - Korean Yangnyeum, Unli Wings - Lemon Glazed, Unli Wings - Mango Habanero, Unli Wings - Original, Unli Wings - Panda Express Orange Chicken, Unli Wings - Salted Egg, Unli Wings - Snow Cheese, Unli Wings - Soy Garlic, Unli Wings - Teriyaki, White Truffle Pasta, Wings Platter 6 pcs w/ Fries, Wings Platter 36 pcs (6 Flavors) | K89: Dry, sealed, ambient | L89: Indefinite (best 24 months) | M89: Opened: indefinite if dry | N89: Existing
A90: ING-089 | B90: Salted Egg Yolk | C90: Dairy/Eggs | D90: Cured salted duck egg yolk | E90: pc | F90: 10 | G90: pc | H90: 1 | I90: =IFERROR(F90/H90,0) -> 10 | J90: Unli Wings - Salted Egg | K90: Chilled 0-4°C | L90: 2-3 weeks (cured) | M90: Use within 3-5 days once cracked | N90: Existing
A91: ING-090 | B91: Sesame Oil | C91: Oils | D91: Toasted sesame oil | E91: L (750ml bottle) | F91: 540 | G91: ml | H91: 750 | I91: =IFERROR(F91/H91,0) -> 0.72 | J91: Spicy Korean Wing Bowl, Unli Wings - Korean BBQ, Unli Wings - Soy Garlic | K91: Cool, dark, ambient | L91: 18-24 months (printed date) | M91: Opened: refrigerate, 6-9 months | N91: Existing
A92: ING-091 | B92: Sesame Seeds | C92: Spices | D92: Toasted sesame seeds | E92: kg | F92: 320 | G92: g | H92: 1000 | I92: =IFERROR(F92/H92,0) -> 0.32 | J92: Spicy Korean Wing Bowl, Unli Wings - Korean BBQ, Unli Wings - Korean Yangnyeum, Unli Wings - Soy Garlic, Unli Wings - Teriyaki | K92: Dry, sealed, ambient | L92: 9-12 months | M92: Opened: 3-6 months, refrigerate | N92: Existing
A93: ING-092 | B93: Soy Sauce | C93: Condiments | D93: All-purpose (dark) soy sauce | E93: L | F93: 65 | G93: ml | H93: 1000 | I93: =IFERROR(F93/H93,0) -> 0.065 | J93: Bacon and 2 Egg, Beef Tapa, Chicken Salpicao, Hungarian Sausage, Pork Tocino, Pork Tonkatsu, Spam and Egg, Spicy Korean Wing Bowl, Unli Wings - Korean BBQ, Unli Wings - Korean Yangnyeum, Unli Wings - Panda Express Orange Chicken, Unli Wings - Soy Garlic, Unli Wings - Teriyaki | K93: Ambient, sealed | L93: 18-24 months (printed date) | M93: Opened: 12+ months ambient | N93: Existing
A94: ING-093 | B94: Spam | C94: Meat | D94: Luncheon meat, canned | E94: can (340g) | F94: 185 | G94: g | H94: 340 | I94: =IFERROR(F94/H94,0) -> 0.54411765 | J94: Spam and Egg | K94: Ambient (dry storage) | L94: 2-3 years (printed date) | M94: Opened: refrigerate, 3-5 days | N94: Existing
A95: ING-094 | B95: Spring Onion | C95: Produce | D95: Fresh spring onion/scallion | E95: kg | F95: 120 | G95: g | H95: 1000 | I95: =IFERROR(F95/H95,0) -> 0.12 | J95: Bacon and 2 Egg, Cheesy Bacon Fries, Hungarian Sausage, Pork Tocino, Spam and Egg, Spicy Korean Wing Bowl | K95: Chilled 0-4°C | L95: 5-7 days | M95: n/a | N95: Existing
A96: ING-095 | B96: Sprite (Can) | C96: Beverages | D96: Sprite, 330ml can | E96: can (330ml) | F96: 38 | G96: can | H96: 1 | I96: =IFERROR(F96/H96,0) -> 38 | J96: Sprite | K96: Ambient, sealed | L96: 6-9 months (printed date) | M96: n/a | N96: Existing
... A109: ING-108 | B109: Coke Zero (Can) | C109: Beverages | D109: Coca-Cola Zero Sugar, 330ml can. Purchase price assumed equal to regular Coke (same brand, same can size) -- replace with the supplier quote when available. | E109: can (330ml) | F109: 38 | G109: can | H109: 1 | I109: =IFERROR(F109/H109,0) -> 38 | J109: Coke Zero | K109: Ambient, sealed | L109: 6-9 months (printed date) | M109: n/a | N109: Added

Sheet 6. Menu-to-Ingredient Mapping
K1: Oil Absorption Factor (assumption) | L1: 0.08 | M1: Applied only to "Cooking Oil" lines of >=100ml (i.e. deep-frying volume, not a small mixed-in amount). Edit this cell to recalculate every adjusted cost in Table 6 and Table 7. | S1: Cooking Oil per Wing, ml (assumption) | T1: 5 | U1: Owner-set default (5ml/wing) applied to every Unlimited Wings flavor and all three Ala Carte Wings items and the Sulit Deal -- replaces the old fryer-volume convention for wings specifically. Recipe Quantity (col D) for these items' Cooking Oil line is a live formula = wings served x this cell, so editing it recalculates every wing item's oil cost/deduction automatically. Unlimited Wings should scale this with actual wings served including refills at order time. Replace with a measured rate when available. | AA1: Cooking Oil per Fish & Chips with Tartar Sauce serving, ml (assumption) | AB1: 30 | AC1: Owner-set estimate (2026-09-25), same style as the wing oil rate (cell T1). Replaces the old fryer-volume + 8%-absorption-factor guess for this item. Recipe Quantity (col D) for this item's Cooking Oil line is a live formula = this cell, so it recalculates the moment you edit it. Replace with a measured rate once the kitchen weighs actual oil use. | AD1: Cooking Oil per Onion Rings serving, ml (assumption) | AE1: 20 | AF1: Owner-set estimate (2026-09-25), same style as the wing oil rate (cell T1). Replaces the old fryer-volume + 8%-absorption-factor guess for this item. Recipe Quantity (col D) for this item's Cooking Oil line is a live formula = this cell, so it recalculates the moment you edit it. Replace with a measured rate once the kitchen weighs actual oil use. | AG1: Cooking Oil per Cheesy Bacon Fries serving, ml (assumption) | AH1: 15 | AI1: Owner-set estimate (2026-09-25), same style as the wing oil rate (cell T1). Replaces the old fryer-volume + 8%-absorption-factor guess for this item. Recipe Quantity (col D) for this item's Cooking Oil line is a live formula = this cell, so it recalculates the moment you edit it. Replace with a measured rate once the kitchen weighs actual oil use.
A3: Menu Item | B3: Category | C3: Ingredient Name (standardized) | D3: Recipe Quantity | E3: Recipe Unit | F3: Base Qty | G3: Cost per Base Unit (₱) | H3: Line Cost -- As Written (₱) | I3: Oil-Adjusted Base Qty | J3: Line Cost -- Oil-Adjusted (₱)
A4: Unli Wings - Classic Buffalo | B4: Unlimited Wings - 14 Flavors | C4: Chicken Wings | D4: 3 | E4: pc | F4: =$D4*1 -> 3 | G4: =IFERROR(INDEX('4. Master Ingredient Inventory'!$I$2:$I$109,MATCH($C4,'4. Master Ingredient Inventory'!$B$2:$B$109,0)),0) -> 13.77 | H4: =$F4*$G4 -> 41.31 | I4: =IF(AND($C4="Cooking Oil",$D4>=100),$D4*$L$1,$F4) -> 3 | J4: =$I4*$G4 -> 41.31
A5: Unli Wings - Classic Buffalo | B5: Unlimited Wings - 14 Flavors | C5: All-Purpose Flour | D5: 22.5 | E5: g | F5: =$D5*1 -> 22.5 | G5: =IFERROR(INDEX('4. Master Ingredient Inventory'!$I$2:$I$109,MATCH($C5,'4. Master Ingredient Inventory'!$B$2:$B$109,0)),0) -> 0.058 | H5: =$F5*$G5 -> 1.305 | I5: =IF(AND($C5="Cooking Oil",$D5>=100),$D5*$L$1,$F5) -> 22.5 | J5: =$I5*$G5 -> 1.305
A6: Unli Wings - Classic Buffalo | B6: Unlimited Wings - 14 Flavors | C6: Cornstarch | D6: 15 | E6: g | F6: =$D6*1 -> 15 | G6: =IFERROR(INDEX('4. Master Ingredient Inventory'!$I$2:$I$109,MATCH($C6,'4. Master Ingredient Inventory'!$B$2:$B$109,0)),0) -> 0.075 | H6: =$F6*$G6 -> 1.125 | I6: =IF(AND($C6="Cooking Oil",$D6>=100),$D6*$L$1,$F6) -> 15 | J6: =$I6*$G6 -> 1.125
A7: Unli Wings - Classic Buffalo | B7: Unlimited Wings - 14 Flavors | C7: Baking Powder | D7: 1 | E7: g | F7: =$D7*1 -> 1 | G7: =IFERROR(INDEX('4. Master Ingredient Inventory'!$I$2:$I$109,MATCH($C7,'4. Master Ingredient Inventory'!$B$2:$B$109,0)),0) -> 0.14 | H7: =$F7*$G7 -> 0.14 | I7: =IF(AND($C7="Cooking Oil",$D7>=100),$D7*$L$1,$F7) -> 1 | J7: =$I7*$G7 -> 0.14
A8: Unli Wings - Classic Buffalo | B8: Unlimited Wings - 14 Flavors | C8: Salt | D8: 1 | E8: g | F8: =$D8*1 -> 1 | G8: =IFERROR(INDEX('4. Master Ingredient Inventory'!$I$2:$I$109,MATCH($C8,'4. Master Ingredient Inventory'!$B$2:$B$109,0)),0) -> 0.03 | H8: =$F8*$G8 -> 0.03 | I8: =IF(AND($C8="Cooking Oil",$D8>=100),$D8*$L$1,$F8) -> 1 | J8: =$I8*$G8 -> 0.03
A9: Unli Wings - Classic Buffalo | B9: Unlimited Wings - 14 Flavors | C9: Black Pepper (ground) | D9: 0.5 | E9: g | F9: =$D9*1 -> 0.5 | G9: =IFERROR(INDEX('4. Master Ingredient Inventory'!$I$2:$I$109,MATCH($C9,'4. Master Ingredient Inventory'!$B$2:$B$109,0)),0) -> 0.65 | H9: =$F9*$G9 -> 0.325 | I9: =IF(AND($C9="Cooking Oil",$D9>=100),$D9*$L$1,$F9) -> 0.5 | J9: =$I9*$G9 -> 0.325
A10: Unli Wings - Classic Buffalo | B10: Unlimited Wings - 14 Flavors | C10: Garlic Powder | D10: 0.5 | E10: g | F10: =$D10*1 -> 0.5 | G10: =IFERROR(INDEX('4. Master Ingredient Inventory'!$I$2:$I$109,MATCH($C10,'4. Master Ingredient Inventory'!$B$2:$B$109,0)),0) -> 0.28 | H10: =$F10*$G10 -> 0.14 | I10: =IF(AND($C10="Cooking Oil",$D10>=100),$D10*$L$1,$F10) -> 0.5 | J10: =$I10*$G10 -> 0.14
A11: Unli Wings - Classic Buffalo | B11: Unlimited Wings - 14 Flavors | C11: Cooking Oil | D11: =3*$T$1 -> 15 | E11: ml | F11: =$D11*1 -> 15 | G11: =IFERROR(INDEX('4. Master Ingredient Inventory'!$I$2:$I$109,MATCH($C11,'4. Master Ingredient Inventory'!$B$2:$B$109,0)),0) -> 0.09 | H11: =$F11*$G11 -> 1.35 | I11: =IF(AND($C11="Cooking Oil",$D11>=100),$D11*$L$1,$F11) -> 15 | J11: =$I11*$G11 -> 1.35
A12: Unli Wings - Classic Buffalo | B12: Unlimited Wings - 14 Flavors | C12: Hot Sauce | D12: 22.5 | E12: ml | F12: =$D12*1 -> 22.5 | G12: =IFERROR(INDEX('4. Master Ingredient Inventory'!$I$2:$I$109,MATCH($C12,'4. Master Ingredient Inventory'!$B$2:$B$109,0)),0) -> 0.25 | H12: =$F12*$G12 -> 5.625 | I12: =IF(AND($C12="Cooking Oil",$D12>=100),$D12*$L$1,$F12) -> 22.5 | J12: =$I12*$G12 -> 5.625
A13: Unli Wings - Classic Buffalo | B13: Unlimited Wings - 14 Flavors | C13: Butter | D13: 9 | E13: g | F13: =$D13*1 -> 9 | G13: =IFERROR(INDEX('4. Master Ingredient Inventory'!$I$2:$I$109,MATCH($C13,'4. Master Ingredient Inventory'!$B$2:$B$109,0)),0) -> 0.48 | H13: =$F13*$G13 -> 4.32 | I13: =IF(AND($C13="Cooking Oil",$D13>=100),$D13*$L$1,$F13) -> 9 | J13: =$I13*$G13 -> 4.32
A14: Unli Wings - Classic Buffalo | B14: Unlimited Wings - 14 Flavors | C14: Worcestershire Sauce | D14: 1.5 | E14: ml | F14: =$D14*1 -> 1.5 | G14: =IFERROR(INDEX('4. Master Ingredient Inventory'!$I$2:$I$109,MATCH($C14,'4. Master Ingredient Inventory'!$B$2:$B$109,0)),0) -> 0.28 | H14: =$F14*$G14 -> 0.42 | I14: =IF(AND($C14="Cooking Oil",$D14>=100),$D14*$L$1,$F14) -> 1.5 | J14: =$I14*$G14 -> 0.42
A15: Unli Wings - Mango Habanero | B15: Unlimited Wings - 14 Flavors | C15: Chicken Wings | D15: 3 | E15: pc | F15: =$D15*1 -> 3 | G15: =IFERROR(INDEX('4. Master Ingredient Inventory'!$I$2:$I$109,MATCH($C15,'4. Master Ingredient Inventory'!$B$2:$B$109,0)),0) -> 13.77 | H15: =$F15*$G15 -> 41.31 | I15: =IF(AND($C15="Cooking Oil",$D15>=100),$D15*$L$1,$F15) -> 3 | J15: =$I15*$G15 -> 41.31
A16: Unli Wings - Mango Habanero | B16: Unlimited Wings - 14 Flavors | C16: All-Purpose Flour | D16: 22.5 | E16: g | F16: =$D16*1 -> 22.5 | G16: =IFERROR(INDEX('4. Master Ingredient Inventory'!$I$2:$I$109,MATCH($C16,'4. Master Ingredient Inventory'!$B$2:$B$109,0)),0) -> 0.058 | H16: =$F16*$G16 -> 1.305 | I16: =IF(AND($C16="Cooking Oil",$D16>=100),$D16*$L$1,$F16) -> 22.5 | J16: =$I16*$G16 -> 1.305
A17: Unli Wings - Mango Habanero | B17: Unlimited Wings - 14 Flavors | C17: Cornstarch | D17: 15 | E17: g | F17: =$D17*1 -> 15 | G17: =IFERROR(INDEX('4. Master Ingredient Inventory'!$I$2:$I$109,MATCH($C17,'4. Master Ingredient Inventory'!$B$2:$B$109,0)),0) -> 0.075 | H17: =$F17*$G17 -> 1.125 | I17: =IF(AND($C17="Cooking Oil",$D17>=100),$D17*$L$1,$F17) -> 15 | J17: =$I17*$G17 -> 1.125
A18: Unli Wings - Mango Habanero | B18: Unlimited Wings - 14 Flavors | C18: Baking Powder | D18: 1 | E18: g | F18: =$D18*1 -> 1 | G18: =IFERROR(INDEX('4. Master Ingredient Inventory'!$I$2:$I$109,MATCH($C18,'4. Master Ingredient Inventory'!$B$2:$B$109,0)),0) -> 0.14 | H18: =$F18*$G18 -> 0.14 | I18: =IF(AND($C18="Cooking Oil",$D18>=100),$D18*$L$1,$F18) -> 1 | J18: =$I18*$G18 -> 0.14
A19: Unli Wings - Mango Habanero | B19: Unlimited Wings - 14 Flavors | C19: Salt | D19: 1 | E19: g | F19: =$D19*1 -> 1 | G19: =IFERROR(INDEX('4. Master Ingredient Inventory'!$I$2:$I$109,MATCH($C19,'4. Master Ingredient Inventory'!$B$2:$B$109,0)),0) -> 0.03 | H19: =$F19*$G19 -> 0.03 | I19: =IF(AND($C19="Cooking Oil",$D19>=100),$D19*$L$1,$F19) -> 1 | J19: =$I19*$G19 -> 0.03
A20: Unli Wings - Mango Habanero | B20: Unlimited Wings - 14 Flavors | C20: Black Pepper (ground) | D20: 0.5 | E20: g | F20: =$D20*1 -> 0.5 | G20: =IFERROR(INDEX('4. Master Ingredient Inventory'!$I$2:$I$109,MATCH($C20,'4. Master Ingredient Inventory'!$B$2:$B$109,0)),0) -> 0.65 | H20: =$F20*$G20 -> 0.325 | I20: =IF(AND($C20="Cooking Oil",$D20>=100),$D20*$L$1,$F20) -> 0.5 | J20: =$I20*$G20 -> 0.325
A21: Unli Wings - Mango Habanero | B21: Unlimited Wings - 14 Flavors | C21: Garlic Powder | D21: 0.5 | E21: g | F21: =$D21*1 -> 0.5 | G21: =IFERROR(INDEX('4. Master Ingredient Inventory'!$I$2:$I$109,MATCH($C21,'4. Master Ingredient Inventory'!$B$2:$B$109,0)),0) -> 0.28 | H21: =$F21*$G21 -> 0.14 | I21: =IF(AND($C21="Cooking Oil",$D21>=100),$D21*$L$1,$F21) -> 0.5 | J21: =$I21*$G21 -> 0.14
A22: Unli Wings - Mango Habanero | B22: Unlimited Wings - 14 Flavors | C22: Cooking Oil | D22: =3*$T$1 -> 15 | E22: ml | F22: =$D22*1 -> 15 | G22: =IFERROR(INDEX('4. Master Ingredient Inventory'!$I$2:$I$109,MATCH($C22,'4. Master Ingredient Inventory'!$B$2:$B$109,0)),0) -> 0.09 | H22: =$F22*$G22 -> 1.35 | I22: =IF(AND($C22="Cooking Oil",$D22>=100),$D22*$L$1,$F22) -> 15 | J22: =$I22*$G22 -> 1.35
A23: Unli Wings - Mango Habanero | B23: Unlimited Wings - 14 Flavors | C23: Mango Nectar/Puree | D23: 27.5 | E23: ml | F23: =$D23*1 -> 27.5 | G23: =IFERROR(INDEX('4. Master Ingredient Inventory'!$I$2:$I$109,MATCH($C23,'4. Master Ingredient Inventory'!$B$2:$B$109,0)),0) -> 0.16 | H23: =$F23*$G23 -> 4.4 | I23: =IF(AND($C23="Cooking Oil",$D23>=100),$D23*$L$1,$F23) -> 27.5 | J23: =$I23*$G23 -> 4.4
A24: Unli Wings - Mango Habanero | B24: Unlimited Wings - 14 Flavors | C24: Habanero Sauce | D24: 5 | E24: ml | F24: =$D24*1 -> 5 | G24: =IFERROR(INDEX('4. Master Ingredient Inventory'!$I$2:$I$109,MATCH($C24,'4. Master Ingredient Inventory'!$B$2:$B$109,0)),0) -> 0.45 | H24: =$F24*$G24 -> 2.25 | I24: =IF(AND($C24="Cooking Oil",$D24>=100),$D24*$L$1,$F24) -> 5 | J24: =$I24*$G24 -> 2.25
A25: Unli Wings - Mango Habanero | B25: Unlimited Wings - 14 Flavors | C25: Honey | D25: 4 | E25: g | F25: =$D25*1 -> 4 | G25: =IFERROR(INDEX('4. Master Ingredient Inventory'!$I$2:$I$109,MATCH($C25,'4. Master Ingredient Inventory'!$B$2:$B$109,0)),0) -> 0.32 | H25: =$F25*$G25 -> 1.28 | I25: =IF(AND($C25="Cooking Oil",$D25>=100),$D25*$L$1,$F25) -> 4 | J25: =$I25*$G25 -> 1.28
A26: Unli Wings - Mango Habanero | B26: Unlimited Wings - 14 Flavors | C26: Butter | D26: 4 | E26: g | F26: =$D26*1 -> 4 | G26: =IFERROR(INDEX('4. Master Ingredient Inventory'!$I$2:$I$109,MATCH($C26,'4. Master Ingredient Inventory'!$B$2:$B$109,0)),0) -> 0.48 | H26: =$F26*$G26 -> 1.92 | I26: =IF(AND($C26="Cooking Oil",$D26>=100),$D26*$L$1,$F26) -> 4 | J26: =$I26*$G26 -> 1.92
A27: Unli Wings - Mango Habanero | B27: Unlimited Wings - 14 Flavors | C27: Vinegar (cane/white) | D27: 1.5 | E27: ml | F27: =$D27*1 -> 1.5 | G27: =IFERROR(INDEX('4. Master Ingredient Inventory'!$I$2:$I$109,MATCH($C27,'4. Master Ingredient Inventory'!$B$2:$B$109,0)),0) -> 0.05 | H27: =$F27*$G27 -> 0.075 | I27: =IF(AND($C27="Cooking Oil",$D27>=100),$D27*$L$1,$F27) -> 1.5 | J27: =$I27*$G27 -> 0.075
A28: Unli Wings - Salted Egg | B28: Unlimited Wings - 14 Flavors | C28: Chicken Wings | D28: 3 | E28: pc | F28: =$D28*1 -> 3 | G28: =IFERROR(INDEX('4. Master Ingredient Inventory'!$I$2:$I$109,MATCH($C28,'4. Master Ingredient Inventory'!$B$2:$B$109,0)),0) -> 13.77 | H28: =$F28*$G28 -> 41.31 | I28: =IF(AND($C28="Cooking Oil",$D28>=100),$D28*$L$1,$F28) -> 3 | J28: =$I28*$G28 -> 41.31
A29: Unli Wings - Salted Egg | B29: Unlimited Wings - 14 Flavors | C29: All-Purpose Flour | D29: 22.5 | E29: g | F29: =$D29*1 -> 22.5 | G29: =IFERROR(INDEX('4. Master Ingredient Inventory'!$I$2:$I$109,MATCH($C29,'4. Master Ingredient Inventory'!$B$2:$B$109,0)),0) -> 0.058 | H29: =$F29*$G29 -> 1.305 | I29: =IF(AND($C29="Cooking Oil",$D29>=100),$D29*$L$1,$F29) -> 22.5 | J29: =$I29*$G29 -> 1.305
A30: Unli Wings - Salted Egg | B30: Unlimited Wings - 14 Flavors | C30: Cornstarch | D30: 15 | E30: g | F30: =$D30*1 -> 15 | G30: =IFERROR(INDEX('4. Master Ingredient Inventory'!$I$2:$I$109,MATCH($C30,'4. Master Ingredient Inventory'!$B$2:$B$109,0)),0) -> 0.075 | H30: =$F30*$G30 -> 1.125 | I30: =IF(AND($C30="Cooking Oil",$D30>=100),$D30*$L$1,$F30) -> 15 | J30: =$I30*$G30 -> 1.125
A31: Unli Wings - Salted Egg | B31: Unlimited Wings - 14 Flavors | C31: Baking Powder | D31: 1 | E31: g | F31: =$D31*1 -> 1 | G31: =IFERROR(INDEX('4. Master Ingredient Inventory'!$I$2:$I$109,MATCH($C31,'4. Master Ingredient Inventory'!$B$2:$B$109,0)),0) -> 0.14 | H31: =$F31*$G31 -> 0.14 | I31: =IF(AND($C31="Cooking Oil",$D31>=100),$D31*$L$1,$F31) -> 1 | J31: =$I31*$G31 -> 0.14
A32: Unli Wings - Salted Egg | B32: Unlimited Wings - 14 Flavors | C32: Salt | D32: 1 | E32: g | F32: =$D32*1 -> 1 | G32: =IFERROR(INDEX('4. Master Ingredient Inventory'!$I$2:$I$109,MATCH($C32,'4. Master Ingredient Inventory'!$B$2:$B$109,0)),0) -> 0.03 | H32: =$F32*$G32 -> 0.03 | I32: =IF(AND($C32="Cooking Oil",$D32>=100),$D32*$L$1,$F32) -> 1 | J32: =$I32*$G32 -> 0.03
A33: Unli Wings - Salted Egg | B33: Unlimited Wings - 14 Flavors | C33: Black Pepper (ground) | D33: 0.5 | E33: g | F33: =$D33*1 -> 0.5 | G33: =IFERROR(INDEX('4. Master Ingredient Inventory'!$I$2:$I$109,MATCH($C33,'4. Master Ingredient Inventory'!$B$2:$B$109,0)),0) -> 0.65 | H33: =$F33*$G33 -> 0.325 | I33: =IF(AND($C33="Cooking Oil",$D33>=100),$D33*$L$1,$F33) -> 0.5 | J33: =$I33*$G33 -> 0.325
A34: Unli Wings - Salted Egg | B34: Unlimited Wings - 14 Flavors | C34: Garlic Powder | D34: 0.5 | E34: g | F34: =$D34*1 -> 0.5 | G34: =IFERROR(INDEX('4. Master Ingredient Inventory'!$I$2:$I$109,MATCH($C34,'4. Master Ingredient Inventory'!$B$2:$B$109,0)),0) -> 0.28 | H34: =$F34*$G34 -> 0.14 | I34: =IF(AND($C34="Cooking Oil",$D34>=100),$D34*$L$1,$F34) -> 0.5 | J34: =$I34*$G34 -> 0.14
A35: Unli Wings - Salted Egg | B35: Unlimited Wings - 14 Flavors | C35: Cooking Oil | D35: =3*$T$1 -> 15 | E35: ml | F35: =$D35*1 -> 15 | G35: =IFERROR(INDEX('4. Master Ingredient Inventory'!$I$2:$I$109,MATCH($C35,'4. Master Ingredient Inventory'!$B$2:$B$109,0)),0) -> 0.09 | H35: =$F35*$G35 -> 1.35 | I35: =IF(AND($C35="Cooking Oil",$D35>=100),$D35*$L$1,$F35) -> 15 | J35: =$I35*$G35 -> 1.35
A36: Unli Wings - Salted Egg | B36: Unlimited Wings - 14 Flavors | C36: Salted Egg Yolk | D36: 1 | E36: pc | F36: =$D36*1 -> 1 | G36: =IFERROR(INDEX('4. Master Ingredient Inventory'!$I$2:$I$109,MATCH($C36,'4. Master Ingredient Inventory'!$B$2:$B$109,0)),0) -> 10 | H36: =$F36*$G36 -> 10 | I36: =IF(AND($C36="Cooking Oil",$D36>=100),$D36*$L$1,$F36) -> 1 | J36: =$I36*$G36 -> 10
A37: Unli Wings - Salted Egg | B37: Unlimited Wings - 14 Flavors | C37: Butter | D37: 7.5 | E37: g | F37: =$D37*1 -> 7.5 | G37: =IFERROR(INDEX('4. Master Ingredient Inventory'!$I$2:$I$109,MATCH($C37,'4. Master Ingredient Inventory'!$B$2:$B$109,0)),0) -> 0.48 | H37: =$F37*$G37 -> 3.6 | I37: =IF(AND($C37="Cooking Oil",$D37>=100),$D37*$L$1,$F37) -> 7.5 | J37: =$I37*$G37 -> 3.6
A38: Unli Wings - Salted Egg | B38: Unlimited Wings - 14 Flavors | C38: Garlic (Minced, g) | D38: 2.5 | E38: g | F38: =$D38*1 -> 2.5 | G38: =IFERROR(INDEX('4. Master Ingredient Inventory'!$I$2:$I$109,MATCH($C38,'4. Master Ingredient Inventory'!$B$2:$B$109,0)),0) -> 0.18 | H38: =$F38*$G38 -> 0.45 | I38: =IF(AND($C38="Cooking Oil",$D38>=100),$D38*$L$1,$F38) -> 2.5 | J38: =$I38*$G38 -> 0.45
A39: Unli Wings - Salted Egg | B39: Unlimited Wings - 14 Flavors | C39: Evaporated Milk | D39: 10 | E39: ml | F39: =$D39*1 -> 10 | G39: =IFERROR(INDEX('4. Master Ingredient Inventory'!$I$2:$I$109,MATCH($C39,'4. Master Ingredient Inventory'!$B$2:$B$109,0)),0) -> 0.12972973 | H39: =$F39*$G39 -> 1.2972973 | I39: =IF(AND($C39="Cooking Oil",$D39>=100),$D39*$L$1,$F39) -> 10 | J39: =$I39*$G39 -> 1.2972973
A40: Unli Wings - Salted Egg | B40: Unlimited Wings - 14 Flavors | C40: Chili Flakes | D40: 0.5 | E40: g | F40: =$D40*1 -> 0.5 | G40: =IFERROR(INDEX('4. Master Ingredient Inventory'!$I$2:$I$109,MATCH($C40,'4. Master Ingredient Inventory'!$B$2:$B$109,0)),0) -> 0.28 | H40: =$F40*$G40 -> 0.14 | I40: =IF(AND($C40="Cooking Oil",$D40>=100),$D40*$L$1,$F40) -> 0.5 | J40: =$I40*$G40 -> 0.14
A41: Unli Wings - Salted Egg | B41: Unlimited Wings - 14 Flavors | C41: Curry Leaves | D41: 1 | E41: g | F41: =$D41*1 -> 1 | G41: =IFERROR(INDEX('4. Master Ingredient Inventory'!$I$2:$I$109,MATCH($C41,'4. Master Ingredient Inventory'!$B$2:$B$109,0)),0) -> 0.8 | H41: =$F41*$G41 -> 0.8 | I41: =IF(AND($C41="Cooking Oil",$D41>=100),$D41*$L$1,$F41) -> 1 | J41: =$I41*$G41 -> 0.8
...

Sheet 7. Ingredient & Recipe Costing
A1: Menu Item | B1: Category | C1: Menu Price (₱) | D1: Ingredient Cost -- As Written (₱) | E1: Ingredient Cost -- Oil-Adjusted (₱) | F1: Food Cost % -- As Written | G1: Food Cost % -- Oil-Adjusted
A2: Unli Wings - Classic Buffalo | B2: Unlimited Wings - 14 Flavors | C2: 399 | D2: =SUMIF('6. Menu-to-Ingredient Mapping'!$A:$A,$A2,'6. Menu-to-Ingredient Mapping'!$H:$H) -> 56.09 | E2: =SUMIF('6. Menu-to-Ingredient Mapping'!$A:$A,$A2,'6. Menu-to-Ingredient Mapping'!$J:$J) -> 56.09 | F2: =$D2/$C2 -> 0.14057644 | G2: =$E2/$C2 -> 0.14057644
A3: Unli Wings - Mango Habanero | B3: Unlimited Wings - 14 Flavors | C3: 399 | D3: =SUMIF('6. Menu-to-Ingredient Mapping'!$A:$A,$A3,'6. Menu-to-Ingredient Mapping'!$H:$H) -> 55.65 | E3: =SUMIF('6. Menu-to-Ingredient Mapping'!$A:$A,$A3,'6. Menu-to-Ingredient Mapping'!$J:$J) -> 55.65 | F3: =$D3/$C3 -> 0.13947368 | G3: =$E3/$C3 -> 0.13947368
A4: Unli Wings - Salted Egg | B4: Unlimited Wings - 14 Flavors | C4: 399 | D4: =SUMIF('6. Menu-to-Ingredient Mapping'!$A:$A,$A4,'6. Menu-to-Ingredient Mapping'!$H:$H) -> 62.044297 | E4: =SUMIF('6. Menu-to-Ingredient Mapping'!$A:$A,$A4,'6. Menu-to-Ingredient Mapping'!$J:$J) -> 62.044297 | F4: =$D4/$C4 -> 0.15549949 | G4: =$E4/$C4 -> 0.15549949
A5: Unli Wings - Lemon Glazed | B5: Unlimited Wings - 14 Flavors | C5: 399 | D5: =SUMIF('6. Menu-to-Ingredient Mapping'!$A:$A,$A5,'6. Menu-to-Ingredient Mapping'!$H:$H) -> 53.035 | E5: =SUMIF('6. Menu-to-Ingredient Mapping'!$A:$A,$A5,'6. Menu-to-Ingredient Mapping'!$J:$J) -> 53.035 | F5: =$D5/$C5 -> 0.1329198 | G5: =$E5/$C5 -> 0.1329198
A6: Unli Wings - Original | B6: Unlimited Wings - 14 Flavors | C6: 399 | D6: =SUMIF('6. Menu-to-Ingredient Mapping'!$A:$A,$A6,'6. Menu-to-Ingredient Mapping'!$H:$H) -> 45.865 | E6: =SUMIF('6. Menu-to-Ingredient Mapping'!$A:$A,$A6,'6. Menu-to-Ingredient Mapping'!$J:$J) -> 45.865 | F6: =$D6/$C6 -> 0.11494987 | G6: =$E6/$C6 -> 0.11494987
A7: Unli Wings - Korean BBQ | B7: Unlimited Wings - 14 Flavors | C7: 399 | D7: =SUMIF('6. Menu-to-Ingredient Mapping'!$A:$A,$A7,'6. Menu-to-Ingredient Mapping'!$H:$H) -> 55.7675 | E7: =SUMIF('6. Menu-to-Ingredient Mapping'!$A:$A,$A7,'6. Menu-to-Ingredient Mapping'!$J:$J) -> 55.7675 | F7: =$D7/$C7 -> 0.13976817 | G7: =$E7/$C7 -> 0.13976817
A8: Unli Wings - Garlic Parmesan | B8: Unlimited Wings - 14 Flavors | C8: 399 | D8: =SUMIF('6. Menu-to-Ingredient Mapping'!$A:$A,$A8,'6. Menu-to-Ingredient Mapping'!$H:$H) -> 59.393333 | E8: =SUMIF('6. Menu-to-Ingredient Mapping'!$A:$A,$A8,'6. Menu-to-Ingredient Mapping'!$J:$J) -> 59.393333 | F8: =$D8/$C8 -> 0.14885547 | G8: =$E8/$C8 -> 0.14885547
A9: Unli Wings - Soy Garlic | B9: Unlimited Wings - 14 Flavors | C9: 399 | D9: =SUMIF('6. Menu-to-Ingredient Mapping'!$A:$A,$A9,'6. Menu-to-Ingredient Mapping'!$H:$H) -> 52.7285 | E9: =SUMIF('6. Menu-to-Ingredient Mapping'!$A:$A,$A9,'6. Menu-to-Ingredient Mapping'!$J:$J) -> 52.7285 | F9: =$D9/$C9 -> 0.13215163 | G9: =$E9/$C9 -> 0.13215163
A10: Unli Wings - Teriyaki | B10: Unlimited Wings - 14 Flavors | C10: 399 | D10: =SUMIF('6. Menu-to-Ingredient Mapping'!$A:$A,$A10,'6. Menu-to-Ingredient Mapping'!$H:$H) -> 49.6295 | E10: =SUMIF('6. Menu-to-Ingredient Mapping'!$A:$A,$A10,'6. Menu-to-Ingredient Mapping'!$J:$J) -> 49.6295 | F10: =$D10/$C10 -> 0.12438471 | G10: =$E10/$C10 -> 0.12438471
A11: Unli Wings - Honey Sriracha | B11: Unlimited Wings - 14 Flavors | C11: 399 | D11: =SUMIF('6. Menu-to-Ingredient Mapping'!$A:$A,$A11,'6. Menu-to-Ingredient Mapping'!$H:$H) -> 54.905 | E11: =SUMIF('6. Menu-to-Ingredient Mapping'!$A:$A,$A11,'6. Menu-to-Ingredient Mapping'!$J:$J) -> 54.905 | F11: =$D11/$C11 -> 0.13760652 | G11: =$E11/$C11 -> 0.13760652
A12: Unli Wings - Snow Cheese | B12: Unlimited Wings - Premium Flavors | C12: 429 | D12: =SUMIF('6. Menu-to-Ingredient Mapping'!$A:$A,$A12,'6. Menu-to-Ingredient Mapping'!$H:$H) -> 55.0175 | E12: =SUMIF('6. Menu-to-Ingredient Mapping'!$A:$A,$A12,'6. Menu-to-Ingredient Mapping'!$J:$J) -> 55.0175 | F12: =$D12/$C12 -> 0.12824592 | G12: =$E12/$C12 -> 0.12824592
A13: Unli Wings - Panda Express Orange Chicken | B13: Unlimited Wings - Premium Flavors | C13: 414 | D13: =SUMIF('6. Menu-to-Ingredient Mapping'!$A:$A,$A13,'6. Menu-to-Ingredient Mapping'!$H:$H) -> 50.0245 | E13: =SUMIF('6. Menu-to-Ingredient Mapping'!$A:$A,$A13,'6. Menu-to-Ingredient Mapping'!$J:$J) -> 50.0245 | F13: =$D13/$C13 -> 0.12083213 | G13: =$E13/$C13 -> 0.12083213
... A49: Wings Platter 36 pcs (6 Flavors) | B49: Ala Carte Wings | C49: 1125 | D49: =SUMIF('6. Menu-to-Ingredient Mapping'!$A:$A,$A49,'6. Menu-to-Ingredient Mapping'!$H:$H) -> 779.88 | E49: =SUMIF('6. Menu-to-Ingredient Mapping'!$A:$A,$A49,'6. Menu-to-Ingredient Mapping'!$J:$J) -> 764.976 | F49: =$D49/$C49 -> 0.69322667 | G49: =$E49/$C49 -> 0.67997867
